WARNING 2023-10-31 22:31:50,063 log 2 139807918233472 Not Found: /static/bootstrap.min.css
ERROR 2023-10-31 22:31:55,314 log 2 139807918233472 Internal Server Error: /about/
Traceback (most recent call last):
  File "/home/CyberMaiber/.virtualenvs/virtualenv/lib/python3.10/site-packages/django/core/handlers/exception.py", line 47, in inner
    response = get_response(request)
  File "/home/CyberMaiber/.virtualenvs/virtualenv/lib/python3.10/site-packages/django/core/handlers/base.py", line 181, in _get_response
    response = wrapped_callback(request, *callback_args, **callback_kwargs)
  File "/home/CyberMaiber/django_dpl/proj_one/./hometask_app/views.py", line 57, in about
    logger.info('About page accessed.',{})
  File "/usr/local/lib/python3.10/logging/__init__.py", line 1477, in info
    self._log(INFO, msg, args, **kwargs)
  File "/usr/local/lib/python3.10/logging/__init__.py", line 1624, in _log
    self.handle(record)
  File "/usr/local/lib/python3.10/logging/__init__.py", line 1634, in handle
    self.callHandlers(record)
  File "/usr/local/lib/python3.10/logging/__init__.py", line 1696, in callHandlers
    hdlr.handle(record)
  File "/usr/local/lib/python3.10/logging/__init__.py", line 968, in handle
    self.emit(record)
  File "/bin/user_wsgi_wrapper.py", line 113, in emit
    format_with_millis(datetime.now()), self.format(record)
  File "/usr/local/lib/python3.10/logging/__init__.py", line 943, in format
    return fmt.format(record)
  File "/usr/local/lib/python3.10/logging/__init__.py", line 678, in format
    record.message = record.getMessage()
  File "/usr/local/lib/python3.10/logging/__init__.py", line 368, in getMessage
    msg = msg % self.args
TypeError: not all arguments converted during string formatting
WARNING 2023-10-31 22:32:04,696 log 2 139807918233472 Not Found: /static/bootstrap.min.css
ERROR 2023-10-31 22:32:12,541 log 2 139807918233472 Internal Server Error: /goods/
Traceback (most recent call last):
  File "/home/CyberMaiber/.virtualenvs/virtualenv/lib/python3.10/site-packages/django/db/backends/utils.py", line 84, in _execute
    return self.cursor.execute(sql, params)
  File "/home/CyberMaiber/.virtualenvs/virtualenv/lib/python3.10/site-packages/django/db/backends/mysql/base.py", line 73, in execute
    return self.cursor.execute(query, args)
  File "/home/CyberMaiber/.virtualenvs/virtualenv/lib/python3.10/site-packages/MySQLdb/cursors.py", line 179, in execute
    res = self._query(mogrified_query)
  File "/home/CyberMaiber/.virtualenvs/virtualenv/lib/python3.10/site-packages/MySQLdb/cursors.py", line 330, in _query
    db.query(q)
  File "/home/CyberMaiber/.virtualenvs/virtualenv/lib/python3.10/site-packages/MySQLdb/connections.py", line 255, in query
    _mysql.connection.query(self, query)
MySQLdb.ProgrammingError: (1146, "Table 'CyberMaiber$default.hometask_app_goodone' doesn't exist")

The above exception was the direct cause of the following exception:

Traceback (most recent call last):
  File "/home/CyberMaiber/.virtualenvs/virtualenv/lib/python3.10/site-packages/django/core/handlers/exception.py", line 47, in inner
    response = get_response(request)
  File "/home/CyberMaiber/.virtualenvs/virtualenv/lib/python3.10/site-packages/django/core/handlers/base.py", line 181, in _get_response
    response = wrapped_callback(request, *callback_args, **callback_kwargs)
  File "/home/CyberMaiber/django_dpl/proj_one/./hometask_app/views.py", line 37, in all_goods_list
    return render(request,'hometask_app/all_goods.html',{'goods':goods})
  File "/home/CyberMaiber/.virtualenvs/virtualenv/lib/python3.10/site-packages/django/shortcuts.py", line 19, in render
    content = loader.render_to_string(template_name, context, request, using=using)
  File "/home/CyberMaiber/.virtualenvs/virtualenv/lib/python3.10/site-packages/django/template/loader.py", line 62, in render_to_string
    return template.render(context, request)
  File "/home/CyberMaiber/.virtualenvs/virtualenv/lib/python3.10/site-packages/django/template/backends/django.py", line 61, in render
    return self.template.render(context)
  File "/home/CyberMaiber/.virtualenvs/virtualenv/lib/python3.10/site-packages/django/template/base.py", line 170, in render
    return self._render(context)
  File "/home/CyberMaiber/.virtualenvs/virtualenv/lib/python3.10/site-packages/django/template/base.py", line 162, in _render
    return self.nodelist.render(context)
  File "/home/CyberMaiber/.virtualenvs/virtualenv/lib/python3.10/site-packages/django/template/base.py", line 938, in render
    bit = node.render_annotated(context)
  File "/home/CyberMaiber/.virtualenvs/virtualenv/lib/python3.10/site-packages/django/template/base.py", line 905, in render_annotated
    return self.render(context)
  File "/home/CyberMaiber/.virtualenvs/virtualenv/lib/python3.10/site-packages/django/template/loader_tags.py", line 150, in render
    return compiled_parent._render(context)
  File "/home/CyberMaiber/.virtualenvs/virtualenv/lib/python3.10/site-packages/django/template/base.py", line 162, in _render
    return self.nodelist.render(context)
  File "/home/CyberMaiber/.virtualenvs/virtualenv/lib/python3.10/site-packages/django/template/base.py", line 938, in render
    bit = node.render_annotated(context)
  File "/home/CyberMaiber/.virtualenvs/virtualenv/lib/python3.10/site-packages/django/template/base.py", line 905, in render_annotated
    return self.render(context)
  File "/home/CyberMaiber/.virtualenvs/virtualenv/lib/python3.10/site-packages/django/template/loader_tags.py", line 62, in render
    result = block.nodelist.render(context)
  File "/home/CyberMaiber/.virtualenvs/virtualenv/lib/python3.10/site-packages/django/template/base.py", line 938, in render
    bit = node.render_annotated(context)
  File "/home/CyberMaiber/.virtualenvs/virtualenv/lib/python3.10/site-packages/django/template/base.py", line 905, in render_annotated
    return self.render(context)
  File "/home/CyberMaiber/.virtualenvs/virtualenv/lib/python3.10/site-packages/django/template/defaulttags.py", line 314, in render
    if match:
  File "/home/CyberMaiber/.virtualenvs/virtualenv/lib/python3.10/site-packages/django/db/models/query.py", line 284, in __bool__
    self._fetch_all()
  File "/home/CyberMaiber/.virtualenvs/virtualenv/lib/python3.10/site-packages/django/db/models/query.py", line 1324, in _fetch_all
    self._result_cache = list(self._iterable_class(self))
  File "/home/CyberMaiber/.virtualenvs/virtualenv/lib/python3.10/site-packages/django/db/models/query.py", line 51, in __iter__
    results = compiler.execute_sql(chunked_fetch=self.chunked_fetch, chunk_size=self.chunk_size)
  File "/home/CyberMaiber/.virtualenvs/virtualenv/lib/python3.10/site-packages/django/db/models/sql/compiler.py", line 1175, in execute_sql
    cursor.execute(sql, params)
  File "/home/CyberMaiber/.virtualenvs/virtualenv/lib/python3.10/site-packages/django/db/backends/utils.py", line 66, in execute
    return self._execute_with_wrappers(sql, params, many=False, executor=self._execute)
  File "/home/CyberMaiber/.virtualenvs/virtualenv/lib/python3.10/site-packages/django/db/backends/utils.py", line 75, in _execute_with_wrappers
    return executor(sql, params, many, context)
  File "/home/CyberMaiber/.virtualenvs/virtualenv/lib/python3.10/site-packages/django/db/backends/utils.py", line 79, in _execute
    with self.db.wrap_database_errors:
  File "/home/CyberMaiber/.virtualenvs/virtualenv/lib/python3.10/site-packages/django/db/utils.py", line 90, in __exit__
    raise dj_exc_value.with_traceback(traceback) from exc_value
  File "/home/CyberMaiber/.virtualenvs/virtualenv/lib/python3.10/site-packages/django/db/backends/utils.py", line 84, in _execute
    return self.cursor.execute(sql, params)
  File "/home/CyberMaiber/.virtualenvs/virtualenv/lib/python3.10/site-packages/django/db/backends/mysql/base.py", line 73, in execute
    return self.cursor.execute(query, args)
  File "/home/CyberMaiber/.virtualenvs/virtualenv/lib/python3.10/site-packages/MySQLdb/cursors.py", line 179, in execute
    res = self._query(mogrified_query)
  File "/home/CyberMaiber/.virtualenvs/virtualenv/lib/python3.10/site-packages/MySQLdb/cursors.py", line 330, in _query
    db.query(q)
  File "/home/CyberMaiber/.virtualenvs/virtualenv/lib/python3.10/site-packages/MySQLdb/connections.py", line 255, in query
    _mysql.connection.query(self, query)
django.db.utils.ProgrammingError: (1146, "Table 'CyberMaiber$default.hometask_app_goodone' doesn't exist")
WARNING 2023-10-31 22:33:54,288 log 2 139807918233472 Not Found: /static/bootstrap.min.css
WARNING 2023-10-31 22:41:24,421 log 2 140230587578240 Not Found: /static/bootstrap.min.css
WARNING 2023-10-31 22:41:26,045 log 2 140230587578240 Not Found: /static/bootstrap.min.css
ERROR 2023-10-31 22:41:27,589 log 2 140230587578240 Internal Server Error: /about/
Traceback (most recent call last):
  File "/home/CyberMaiber/.virtualenvs/virtualenv/lib/python3.10/site-packages/django/core/handlers/exception.py", line 47, in inner
    response = get_response(request)
  File "/home/CyberMaiber/.virtualenvs/virtualenv/lib/python3.10/site-packages/django/core/handlers/base.py", line 181, in _get_response
    response = wrapped_callback(request, *callback_args, **callback_kwargs)
  File "/home/CyberMaiber/django_dpl/proj_one/./hometask_app/views.py", line 57, in about
    logger.info('About page accessed.',{})
  File "/usr/local/lib/python3.10/logging/__init__.py", line 1477, in info
    self._log(INFO, msg, args, **kwargs)
  File "/usr/local/lib/python3.10/logging/__init__.py", line 1624, in _log
    self.handle(record)
  File "/usr/local/lib/python3.10/logging/__init__.py", line 1634, in handle
    self.callHandlers(record)
  File "/usr/local/lib/python3.10/logging/__init__.py", line 1696, in callHandlers
    hdlr.handle(record)
  File "/usr/local/lib/python3.10/logging/__init__.py", line 968, in handle
    self.emit(record)
  File "/bin/user_wsgi_wrapper.py", line 113, in emit
    format_with_millis(datetime.now()), self.format(record)
  File "/usr/local/lib/python3.10/logging/__init__.py", line 943, in format
    return fmt.format(record)
  File "/usr/local/lib/python3.10/logging/__init__.py", line 678, in format
    record.message = record.getMessage()
  File "/usr/local/lib/python3.10/logging/__init__.py", line 368, in getMessage
    msg = msg % self.args
TypeError: not all arguments converted during string formatting
WARNING 2023-10-31 22:41:37,250 log 2 140230587578240 Not Found: /static/bootstrap.min.css
WARNING 2023-10-31 22:42:39,247 log 2 140230587578240 Not Found: /static/bootstrap.min.css
ERROR 2023-10-31 22:51:52,113 log 2 139726990931840 Internal Server Error: /about/
Traceback (most recent call last):
  File "/home/CyberMaiber/.virtualenvs/virtualenv/lib/python3.10/site-packages/django/core/handlers/exception.py", line 47, in inner
    response = get_response(request)
  File "/home/CyberMaiber/.virtualenvs/virtualenv/lib/python3.10/site-packages/django/core/handlers/base.py", line 181, in _get_response
    response = wrapped_callback(request, *callback_args, **callback_kwargs)
  File "/home/CyberMaiber/django_dpl/proj_one/./hometask_app/views.py", line 57, in about
    logger.info('About page accessed.',{})
  File "/usr/local/lib/python3.10/logging/__init__.py", line 1477, in info
    self._log(INFO, msg, args, **kwargs)
  File "/usr/local/lib/python3.10/logging/__init__.py", line 1624, in _log
    self.handle(record)
  File "/usr/local/lib/python3.10/logging/__init__.py", line 1634, in handle
    self.callHandlers(record)
  File "/usr/local/lib/python3.10/logging/__init__.py", line 1696, in callHandlers
    hdlr.handle(record)
  File "/usr/local/lib/python3.10/logging/__init__.py", line 968, in handle
    self.emit(record)
  File "/bin/user_wsgi_wrapper.py", line 113, in emit
    format_with_millis(datetime.now()), self.format(record)
  File "/usr/local/lib/python3.10/logging/__init__.py", line 943, in format
    return fmt.format(record)
  File "/usr/local/lib/python3.10/logging/__init__.py", line 678, in format
    record.message = record.getMessage()
  File "/usr/local/lib/python3.10/logging/__init__.py", line 368, in getMessage
    msg = msg % self.args
TypeError: not all arguments converted during string formatting
ERROR 2023-10-31 22:51:53,957 log 2 139726990931840 Internal Server Error: /about/
Traceback (most recent call last):
  File "/home/CyberMaiber/.virtualenvs/virtualenv/lib/python3.10/site-packages/django/core/handlers/exception.py", line 47, in inner
    response = get_response(request)
  File "/home/CyberMaiber/.virtualenvs/virtualenv/lib/python3.10/site-packages/django/core/handlers/base.py", line 181, in _get_response
    response = wrapped_callback(request, *callback_args, **callback_kwargs)
  File "/home/CyberMaiber/django_dpl/proj_one/./hometask_app/views.py", line 57, in about
    logger.info('About page accessed.',{})
  File "/usr/local/lib/python3.10/logging/__init__.py", line 1477, in info
    self._log(INFO, msg, args, **kwargs)
  File "/usr/local/lib/python3.10/logging/__init__.py", line 1624, in _log
    self.handle(record)
  File "/usr/local/lib/python3.10/logging/__init__.py", line 1634, in handle
    self.callHandlers(record)
  File "/usr/local/lib/python3.10/logging/__init__.py", line 1696, in callHandlers
    hdlr.handle(record)
  File "/usr/local/lib/python3.10/logging/__init__.py", line 968, in handle
    self.emit(record)
  File "/bin/user_wsgi_wrapper.py", line 113, in emit
    format_with_millis(datetime.now()), self.format(record)
  File "/usr/local/lib/python3.10/logging/__init__.py", line 943, in format
    return fmt.format(record)
  File "/usr/local/lib/python3.10/logging/__init__.py", line 678, in format
    record.message = record.getMessage()
  File "/usr/local/lib/python3.10/logging/__init__.py", line 368, in getMessage
    msg = msg % self.args
TypeError: not all arguments converted during string formatting
WARNING 2023-10-31 22:52:11,554 log 2 139726990931840 Not Found: /static/bootstrap.min.css
ERROR 2023-10-31 22:54:40,730 log 2 140641293031296 Internal Server Error: /about/
Traceback (most recent call last):
  File "/home/CyberMaiber/.virtualenvs/virtualenv/lib/python3.10/site-packages/django/core/handlers/exception.py", line 47, in inner
    response = get_response(request)
  File "/home/CyberMaiber/.virtualenvs/virtualenv/lib/python3.10/site-packages/django/core/handlers/base.py", line 181, in _get_response
    response = wrapped_callback(request, *callback_args, **callback_kwargs)
  File "/home/CyberMaiber/django_dpl/proj_one/./hometask_app/views.py", line 57, in about
    logger.info('About page accessed.',{})
  File "/usr/local/lib/python3.10/logging/__init__.py", line 1477, in info
    self._log(INFO, msg, args, **kwargs)
  File "/usr/local/lib/python3.10/logging/__init__.py", line 1624, in _log
    self.handle(record)
  File "/usr/local/lib/python3.10/logging/__init__.py", line 1634, in handle
    self.callHandlers(record)
  File "/usr/local/lib/python3.10/logging/__init__.py", line 1696, in callHandlers
    hdlr.handle(record)
  File "/usr/local/lib/python3.10/logging/__init__.py", line 968, in handle
    self.emit(record)
  File "/bin/user_wsgi_wrapper.py", line 113, in emit
    format_with_millis(datetime.now()), self.format(record)
  File "/usr/local/lib/python3.10/logging/__init__.py", line 943, in format
    return fmt.format(record)
  File "/usr/local/lib/python3.10/logging/__init__.py", line 678, in format
    record.message = record.getMessage()
  File "/usr/local/lib/python3.10/logging/__init__.py", line 368, in getMessage
    msg = msg % self.args
TypeError: not all arguments converted during string formatting
WARNING 2023-10-31 22:56:43,806 log 2 140641293031296 Forbidden (CSRF cookie not set.): /goodedit/1
WARNING 2023-10-31 22:57:30,616 log 2 140641293031296 Forbidden (CSRF cookie not set.): /goodedit/1
WARNING 2023-10-31 22:59:26,971 log 2 140571046434688 Forbidden (CSRF cookie not set.): /admin/login/
WARNING 2023-10-31 23:00:04,960 log 2 140405763635072 Forbidden (CSRF cookie not set.): /admin/login/
WARNING 2023-10-31 23:02:25,301 log 2 140405763635072 Forbidden (CSRF cookie not set.): /admin/login/
WARNING 2023-10-31 23:02:48,947 log 2 140405763635072 Not Found: /favicon.ico
WARNING 2023-10-31 23:02:53,854 log 2 140405763635072 Not Found: /favicon.ico
WARNING 2023-10-31 23:03:05,100 log 2 140405763635072 Forbidden (CSRF cookie not set.): /admin/login/
WARNING 2023-10-31 23:06:44,182 log 2 139991622862720 Forbidden (CSRF cookie not set.): /admin/login/
WARNING 2023-10-31 23:09:13,899 log 2 140060435572608 Forbidden (CSRF cookie not set.): /admin/login/
WARNING 2023-10-31 23:09:22,550 log 2 140060435572608 Forbidden (CSRF cookie not set.): /admin/login/
WARNING 2023-10-31 23:09:48,441 log 2 139997523212160 Forbidden (CSRF cookie not set.): /admin/login/
WARNING 2023-10-31 23:10:53,786 log 2 140249975457664 Forbidden (CSRF cookie not set.): /admin/login/
WARNING 2023-10-31 23:11:08,865 log 2 140249975457664 Forbidden (CSRF cookie not set.): /admin/login/
WARNING 2023-10-31 23:14:07,746 log 2 139766216808320 Forbidden (CSRF cookie not set.): /admin/login/
WARNING 2023-10-31 23:14:44,198 log 2 139766216808320 Forbidden (CSRF cookie not set.): /admin/login/
WARNING 2023-10-31 23:18:35,039 log 2 139766216808320 Not Found: /favicon.ico
WARNING 2023-10-31 23:19:31,121 log 2 139766216808320 Not Found: /favicon.ico
